2024-10-02 06:21:22 | INFO    | __main__:stash:131 | run - {'image': '20231121', 'version': '0.10.1.post2', 'role': 'EpicPlayer', 'headless': True}
2024-10-02 06:21:30 | INFO    | __main__:claim_epic_games:97 | Try to flush cookie - {'task': 'claim_epic_games'}
2024-10-02 06:21:32 | INFO    | epic_games.agent:_login:237 | login-with-email - {'url': 'https://www.epicgames.com/id/login?lang=en-US&noHostRedirect=true&redirectUrl=https://store.epicgames.com/en-US/free-games&__cf_chl_rt_tk=9T2HEUP876nOo8jTK.MtGF9mddJKLACBe1HuE7v4PCc-1727821292-0.0.1.1-6612'}
2024-10-02 06:22:02 | WARNING    | epic_games.agent:authorize:266 | 执行超时 - {'task': 'authorize', 'retry': 0}
2024-10-02 06:22:05 | INFO    | epic_games.agent:_login:237 | login-with-email - {'url': 'https://www.epicgames.com/id/login?lang=en-US&noHostRedirect=true&redirectUrl=https://store.epicgames.com/en-US/free-games&__cf_chl_rt_tk=X7yUjCmRLaPG6144b.2pIl0wzpZ.LKQYLnT8G_OHVWA-1727821325-0.0.1.1-7593'}
2024-10-02 06:22:35 | WARNING    | epic_games.agent:authorize:266 | 执行超时 - {'task': 'authorize', 'retry': 1}
2024-10-02 06:22:37 | INFO    | epic_games.agent:_login:237 | login-with-email - {'url': 'https://www.epicgames.com/id/login?lang=en-US&noHostRedirect=true&redirectUrl=https://store.epicgames.com/en-US/free-games&__cf_chl_rt_tk=giIWSRLQGlrzEFQHDHWFnM1LvPQ5h.TOqCOEaMx5CFE-1727821357-0.0.1.1-8532'}
2024-10-02 06:23:07 | WARNING    | epic_games.agent:authorize:266 | 执行超时 - {'task': 'authorize', 'retry': 2}
2024-10-02 06:23:07 | ERROR    | __main__:run:158 | An error has been caught in function 'run', process 'MainProcess' (3640), thread 'MainThread' (139967240412032): - {}
Traceback (most recent call last):
  File "/home/runner/work/epicgames_action/epicgames_action/epic/src/claim.py", line 162, in <module>
    asyncio.run(run())
  File "/opt/hostedtoolcache/Python/3.10.15/x64/lib/python3.10/asyncio/runners.py", line 44, in run
    return loop.run_until_complete(main)
  File "/opt/hostedtoolcache/Python/3.10.15/x64/lib/python3.10/asyncio/base_events.py", line 636, in run_until_complete
    self.run_forever()
  File "/opt/hostedtoolcache/Python/3.10.15/x64/lib/python3.10/asyncio/base_events.py", line 603, in run_forever
    self._run_once()
  File "/opt/hostedtoolcache/Python/3.10.15/x64/lib/python3.10/asyncio/base_events.py", line 1909, in _run_once
    handle._run()
  File "/opt/hostedtoolcache/Python/3.10.15/x64/lib/python3.10/asyncio/events.py", line 80, in _run
    self._context.run(self._callback, *self._args)
> File "/home/runner/work/epicgames_action/epicgames_action/epic/src/claim.py", line 158, in run
    await agent.stash()
  File "/home/runner/work/epicgames_action/epicgames_action/epic/src/claim.py", line 151, in stash
    await self.claim_epic_games(context)
  File "/home/runner/work/epicgames_action/epicgames_action/epic/src/claim.py", line 98, in claim_epic_games
    if await epic.authorize(page):
  File "/home/runner/work/epicgames_action/epicgames_action/epic/src/epic_games/agent.py", line 269, in authorize
    raise RuntimeError(f"Failed to flush token - agent={self.__class__.__name__}")
RuntimeError: Failed to flush token - agent=EpicGames
